Workbook

Sheet Bonds
A1: Date | B1: US TREASURY CS CPN. STRIP 15/05/38 - SPREAD | C1: US TREASURY BOND 1996 6% 15/02/26 - SPREAD | D1: US TREASURY BOND 1997 6 3/8% 15/08/27 - SPREAD | E1: US TREASURY BOND 1998 5 1/4% 15/11/28 - SPREAD | F1: US TREASURY CS CPN. STRIP 15/05/38 - MOD. DURATION | G1: US TREASURY BOND 1996 6% 15/02/26 - MOD. DURATION | H1: US TREASURY BOND 1997 6 3/8% 15/08/27 - MOD. DURATION | I1: US TREASURY BOND 1998 5 1/4% 15/11/28 - MOD. DURATION | J1: US TREASURY CS CPN. STRIP 15/05/38 - PRICE | K1: US TREASURY BOND 1996 6% 15/02/26 - PRICE | L1: US TREASURY BOND 1997 6 3/8% 15/08/27 - PRICE | M1: US TREASURY BOND 1998 5 1/4% 15/11/28 - PRICE | N1: US TREASURY CS CPN. STRIP 15/05/38 - RED. YIELD | O1: US TREASURY BOND 1996 6% 15/02/26 - RED. YIELD | P1: US TREASURY BOND 1997 6 3/8% 15/08/27 - RED. YIELD | Q1: US TREASURY BOND 1998 5 1/4% 15/11/28 - RED. YIELD | T1: Source: Datastream data provided with the assignment text. Ascending chronological order (oldest date on top).
A2: 42262 | B2: 38.6 | C2: 64.1 | D2: 10.5 | E2: 10.3 | F2: 12.1083 | G2: 0.4087 | H2: 1.7914 | I2: 2.8631 | J2: 56.871 | K2: 100.5664 | L2: 104.9844 | M2: 104.8438 | N2: 4.508 | O2: 4.5417 | P2: 3.653 | Q2: 3.6122
A3: 42263 | B3: 39.6 | C3: 68.9 | D3: 11.6 | E3: 10.9 | F3: 12.1071 | G3: 0.4112 | H3: 1.7938 | I3: 2.8652 | J3: 56.639 | K3: 100.543 | L3: 104.9336 | M3: 104.75 | N3: 4.5399 | O3: 4.6075 | P3: 3.6834 | Q3: 3.6442
A4: 42264 | B4: 39.9 | C4: 69.7 | D4: 10.5 | E4: 10 | F4: 12.1195 | G4: 0.4191 | H4: 1.8022 | I4: 2.874 | J4: 56.886 | K4: 100.5547 | L4: 105.0156 | M4: 104.8828 | N4: 4.5019 | O4: 4.6068 | P4: 3.651 | Q4: 3.6045
A5: 42265 | B5: 40.1 | C5: 44.1 | D5: 10.7 | E5: 8.5 | F5: 12.1186 | G5: 0.4222 | H5: 1.8048 | I5: 2.877 | J5: 56.671 | K5: 100.6641 | L5: 105.0078 | M5: 104.9375 | N5: 4.5315 | O5: 4.3591 | P5: 3.6587 | Q5: 3.5879
A6: 42268 | B6: 40.2 | C6: 43.3 | D6: 11.7 | E6: 8.4 | F6: 12.1169 | G6: 0.4249 | H6: 1.8073 | I6: 2.8795 | J6: 56.408 | K6: 100.6719 | L6: 104.9844 | M6: 104.9063 | N6: 4.5679 | O6: 4.3513 | P6: 3.6745 | Q6: 3.5993
A7: 42269 | B7: 40.2 | C7: 61.1 | D7: 9.2 | E7: 9 | F7: 12.1237 | G7: 0.4272 | H7: 1.8108 | I7: 2.8829 | J7: 56.65 | K7: 100.6016 | L7: 105.1406 | M7: 105.0313 | N7: 4.5324 | O7: 4.5245 | P7: 3.5963 | Q7: 3.5599
A8: 42270 | B8: 40.1 | C8: 56.3 | D8: 9.4 | E8: 8.3 | F8: 12.1203 | G8: 0.4299 | H8: 1.8132 | I8: 2.8852 | J8: 56.286 | K8: 100.625 | L8: 105.0898 | M8: 104.9609 | N8: 4.5834 | O8: 4.4798 | P8: 3.6265 | Q8: 3.5841
A9: 42271 | B9: 42.2 | C9: 46.6 | D9: 10.3 | E9: 11.1 | F9: 12.1167 | G9: 0.4379 | H9: 1.8205 | I9: 2.8917 | J9: 55.592 | K9: 100.6484 | L9: 104.9688 | M9: 104.7188 | N9: 4.6804 | O9: 4.4551 | P9: 3.7004 | Q9: 3.6665
A10: 42272 | B10: 41.9 | C10: 61.8 | D10: 11.1 | E10: 9 | F10: 12.113 | G10: 0.4402 | H10: 1.8228 | I10: 2.894 | J10: 55.221 | K10: 100.5742 | L10: 104.8984 | M10: 104.6563 | N10: 4.7335 | O10: 4.6316 | P10: 3.7406 | Q10: 3.688
A11: 42275 | B11: 43 | C11: 62.2 | D11: 10.5 | E11: 9.6 | F11: 12.1085 | G11: 0.4428 | H11: 1.8254 | I11: 2.8961 | J11: 54.805 | K11: 100.5703 | L11: 104.875 | M11: 104.5625 | N11: 4.7934 | O11: 4.6487 | P11: 3.7562 | Q11: 3.7197
A12: 42276 | B12: 44 | C12: 64.8 | D12: 10.7 | E12: 11.2 | F12: 12.1154 | G12: 0.4453 | H12: 1.8283 | I12: 2.8991 | J12: 55.046 | K12: 100.5664 | L12: 104.9258 | M12: 104.625 | N12: 4.7569 | O12: 4.6657 | P12: 3.7333 | Q12: 3.7005
A13: 42277 | B13: 43.9 | C13: 65.8 | D13: 11.1 | E13: 11.3 | F13: 12.1182 | G13: 0.448 | H13: 1.8309 | I13: 2.9018 | J13: 55.046 | K13: 100.5664 | L13: 104.9258 | M13: 104.625 | N13: 4.756 | O13: 4.6739 | P13: 3.7367 | Q13: 3.7017
... A2611: 45915 | B2611: 35.4 | C2611: -1.4 | D2611: 3.3 | E2611: 9 | F2611: 21.9653 | G2611: 8.164 | H2611: 8.9788 | I2611: 9.9069 | J2611: 49.368 | K2611: 134.1406 | L2611: 140.9844 | M2611: 130.6094 | N2611: 3.1393 | O2611: 2.2941 | P2611: 2.3992 | Q2611: 2.5051

Sheet Stocks
A1: Date | B1: WARNER BROS DISCOVERY SERIES A | C1: VISA 'A' | D1: MICROCHIP TECH. | E1: CONOCOPHILLIPS
A2: 42297 | B2: 29.18 | C2: 76.28 | D2: 23.7 | E2: 53.54
A3: 42298 | B3: 28.81 | C3: 75.46 | D3: 23.58 | E3: 52.97
A4: 42299 | B4: 29.45 | C4: 76.42 | D4: 24.43 | E4: 54.58
A5: 42300 | B5: 29.77 | C5: 77.07 | D5: 24.555 | E5: 54.61
A6: 42303 | B6: 29.29 | C6: 78.18 | D6: 24.255 | E6: 52.95
A7: 42304 | B7: 28.78 | C7: 77.52 | D7: 23.965 | E7: 51.69
A8: 42305 | B8: 29.53 | C8: 78.87 | D8: 24.28 | E8: 53.34
A9: 42306 | B9: 29.37 | C9: 78.51 | D9: 23.695 | E9: 53.62
A10: 42307 | B10: 29.44 | C10: 77.58 | D10: 24.145 | E10: 53.35
A11: 42310 | B11: 30.06 | C11: 75.22 | D11: 24.445 | E11: 54.94
A12: 42311 | B12: 31.08 | C12: 77.9 | D12: 24.41 | E12: 56.73
A13: 42312 | B13: 30.3 | C13: 78.35 | D13: 24.495 | E13: 56.34
... A2611: 45950 | B2611: 18.32 | C2611: 344.4099 | D2611: 67.07 | E2611: 87.06

Sheet Stocks Returns
A1: Date | B1: WARNER BROS DISCOVERY SERIES A | C1: VISA 'A' | D1: MICROCHIP TECH. | E1: CONOCOPHILLIPS
A2: =Stocks!A3 -> 42298 | B2: =Stocks!B3/Stocks!B2-1 -> -0.012679918 | C2: =Stocks!C3/Stocks!C2-1 -> -0.010749869 | D2: =Stocks!D3/Stocks!D2-1 -> -0.0050632911 | E2: =Stocks!E3/Stocks!E2-1 -> -0.010646246
A3: =Stocks!A4 -> 42299 | B3: =Stocks!B4/Stocks!B3-1 -> 0.022214509 | C3: =Stocks!C4/Stocks!C3-1 -> 0.012721972 | D3: =Stocks!D4/Stocks!D3-1 -> 0.036047498 | E3: =Stocks!E4/Stocks!E3-1 -> 0.030394563
A4: =Stocks!A5 -> 42300 | B4: =Stocks!B5/Stocks!B4-1 -> 0.010865874 | C4: =Stocks!C5/Stocks!C4-1 -> 0.0085056268 | D4: =Stocks!D5/Stocks!D4-1 -> 0.0051166598 | E4: =Stocks!E5/Stocks!E4-1 -> 0.00054965189
A5: =Stocks!A6 -> 42303 | B5: =Stocks!B6/Stocks!B5-1 -> -0.016123614 | C5: =Stocks!C6/Stocks!C5-1 -> 0.014402491 | D5: =Stocks!D6/Stocks!D5-1 -> -0.012217471 | E5: =Stocks!E6/Stocks!E5-1 -> -0.030397363
A6: =Stocks!A7 -> 42304 | B6: =Stocks!B7/Stocks!B6-1 -> -0.017412086 | C6: =Stocks!C7/Stocks!C6-1 -> -0.0084420568 | D6: =Stocks!D7/Stocks!D6-1 -> -0.011956298 | E6: =Stocks!E7/Stocks!E6-1 -> -0.023796034
A7: =Stocks!A8 -> 42305 | B7: =Stocks!B8/Stocks!B7-1 -> 0.026059764 | C7: =Stocks!C8/Stocks!C7-1 -> 0.017414861 | D7: =Stocks!D8/Stocks!D7-1 -> 0.013144169 | E7: =Stocks!E8/Stocks!E7-1 -> 0.031921068
A8: =Stocks!A9 -> 42306 | B8: =Stocks!B9/Stocks!B8-1 -> -0.0054182188 | C8: =Stocks!C9/Stocks!C8-1 -> -0.0045644732 | D8: =Stocks!D9/Stocks!D8-1 -> -0.024093904 | E8: =Stocks!E9/Stocks!E8-1 -> 0.0052493438
A9: =Stocks!A10 -> 42307 | B9: =Stocks!B10/Stocks!B9-1 -> 0.0023833844 | C9: =Stocks!C10/Stocks!C9-1 -> -0.011845625 | D9: =Stocks!D10/Stocks!D9-1 -> 0.018991348 | E9: =Stocks!E10/Stocks!E9-1 -> -0.0050354345
A10: =Stocks!A11 -> 42310 | B10: =Stocks!B11/Stocks!B10-1 -> 0.021059783 | C10: =Stocks!C11/Stocks!C10-1 -> -0.030420211 | D10: =Stocks!D11/Stocks!D10-1 -> 0.012424933 | E10: =Stocks!E11/Stocks!E10-1 -> 0.029803187
A11: =Stocks!A12 -> 42311 | B11: =Stocks!B12/Stocks!B11-1 -> 0.033932136 | C11: =Stocks!C12/Stocks!C11-1 -> 0.035628822 | D11: =Stocks!D12/Stocks!D11-1 -> -0.0014317856 | E11: =Stocks!E12/Stocks!E11-1 -> 0.032580997
A12: =Stocks!A13 -> 42312 | B12: =Stocks!B13/Stocks!B12-1 -> -0.025096525 | C12: =Stocks!C13/Stocks!C12-1 -> 0.0057766367 | D12: =Stocks!D13/Stocks!D12-1 -> 0.0034821794 | E12: =Stocks!E13/Stocks!E12-1 -> -0.0068746695
A13: =Stocks!A14 -> 42313 | B13: =Stocks!B14/Stocks!B13-1 -> -0.026072607 | C13: =Stocks!C14/Stocks!C13-1 -> 0.01161455 | D13: =Stocks!D14/Stocks!D13-1 -> -0.022045315 | E13: =Stocks!E14/Stocks!E13-1 -> -0.0010649627
... A2610: =Stocks!A2611 -> 45950 | B2610: =Stocks!B2611/Stocks!B2610-1 -> 0.0071467839 | C2610: =Stocks!C2611/Stocks!C2610-1 -> 0.0073707939 | D2610: =Stocks!D2611/Stocks!D2610-1 -> 0.029707531 | E2610: =Stocks!E2611/Stocks!E2610-1 -> 0.006706753

Sheet 1_Bonds
B2: POINT 1 - Immunized bond portfolio
B6: Rebalancing 1 | C6: 45792 | D6: row in Bonds: | E6: =MATCH($C$6,Bonds!$A:$A,0) -> 2524 | G6: Initial wealth of the block | H6: 100000
B7: Security | C7: Spread (bp) | D7: Mod. duration | E7: Price | F7: YTM (%) | G7: YTM (decimal) | H7: Weight w | I7: Capital invested | J7: No. of bonds | K7: w x duration | L7: w x spread | M7: Future wealth
B8: T-STRIP 15/05/38 | C8: =INDEX(Bonds!B:B,$E$6) -> 35.5 | D8: =INDEX(Bonds!F:F,$E$6) -> 21.6904 | E8: =INDEX(Bonds!J:J,$E$6) -> 52.088 | F8: =INDEX(Bonds!N:N,$E$6) -> 2.9421 | G8: =F8/100 -> 0.029421 | H8: 0.21 | I8: =$H$6*H8 -> 21000 | J8: =I8/E8 -> 403.16388 | K8: =H8*D8 -> 4.554984 | L8: =H8*C8 -> 7.455 | M8: =I8*(1+G8) -> 21617.841
B9: T-BOND 6% 15/02/26 | C9: =INDEX(Bonds!C:C,$E$6) -> -0.6 | D9: =INDEX(Bonds!G:G,$E$6) -> 7.8644 | E9: =INDEX(Bonds!K:K,$E$6) -> 135.3281 | F9: =INDEX(Bonds!O:O,$E$6) -> 2.0949 | G9: =F9/100 -> 0.020949 | H9: 0 | I9: =$H$6*H9 -> 0 | J9: =I9/E9 -> 0 | K9: =H9*D9 -> 0 | L9: =H9*C9 -> 0 | M9: =I9*(1+G9) -> 0
B10: T-BOND 6 3/8% 15/08/27 | C10: =INDEX(Bonds!D:D,$E$6) -> 2.4 | D10: =INDEX(Bonds!H:H,$E$6) -> 8.6914 | E10: =INDEX(Bonds!L:L,$E$6) -> 142.6875 | F10: =INDEX(Bonds!P:P,$E$6) -> 2.1849 | G10: =F10/100 -> 0.021849 | H10: 0.4 | I10: =$H$6*H10 -> 40000 | J10: =I10/E10 -> 280.3329 | K10: =H10*D10 -> 3.47656 | L10: =H10*C10 -> 0.96 | M10: =I10*(1+G10) -> 40873.96
B11: T-BOND 5 1/4% 15/11/28 | C11: =INDEX(Bonds!E:E,$E$6) -> 6.5 | D11: =INDEX(Bonds!I:I,$E$6) -> 9.8272 | E11: =INDEX(Bonds!M:M,$E$6) -> 132.9219 | F11: =INDEX(Bonds!Q:Q,$E$6) -> 2.276 | G11: =F11/100 -> 0.02276 | H11: 0.39 | I11: =$H$6*H11 -> 39000 | J11: =I11/E11 -> 293.40538 | K11: =H11*D11 -> 3.832608 | L11: =H11*C11 -> 2.535 | M11: =I11*(1+G11) -> 39887.64
B12: TOTAL | H12: =SUM(H8:H11) -> 1 | I12: =SUM(I8:I11) -> 100000 | K12: =SUM(K8:K11) -> 11.864152 | L12: =SUM(L8:L11) -> 10.95 | M12: =SUM(M8:M11) -> 102379.44
B14: CONSTRAINT CHECK
B15: Empirical average duration of the 4 bonds | E15: =AVERAGE(D8:D11) -> 12.01835
B16: Portfolio duration | E16: =K12 -> 11.864152
B17: Duration constraint (ptf <= average) | E17: =IF(K12<=AVERAGE(D8:D11)+0.0000001,"RESPECTED","VIOLATED") -> RESPECTED
B18: Empirical average spread of the 4 bonds | E18: =AVERAGE(C8:C11) -> 10.95
B19: Portfolio spread | E19: =L12 -> 10.95
B20: Spread constraint (ptf <= average) | E20: =IF(L12<=AVERAGE(C8:C11)+0.0000001,"RESPECTED","VIOLATED") -> RESPECTED
B21: Maximum weight on a single bond | E21: =MAX(H8:H11) -> 0.4
B22: 40% constraint per bond | E22: =IF(MAX(H8:H11)<=0.4000001,"RESPECTED","VIOLATED") -> RESPECTED
B23: Sum of weights | E23: =H12 -> 1
B25: RESULTS
B26: 1-year future wealth | E26: =M12 -> 102379.44
B27: Annual IRR of the bond portfolio (= risk-free rate) | E27: =M12/$H$6-1 -> 0.02379441
B28: Daily risk-free rate (252 days) | E28: =(1+E27)^(1/252)-1 -> 9.3320763e-05
B31: Rebalancing 2 | C31: 45824 | D31: row in Bonds: | E31: =MATCH($C$31,Bonds!$A:$A,0) -> 2546 | G31: Initial wealth of the block | H31: ='4_ExPost_Wealth'!M27 -> 98240.583
B32: Security | C32: Spread (bp) | D32: Mod. duration | E32: Price | F32: YTM (%) | G32: YTM (decimal) | H32: Weight w | I32: Capital invested | J32: No. of bonds | K32: w x duration | L32: w x spread | M32: Future wealth
B33: T-STRIP 15/05/38 | C33: =INDEX(Bonds!B:B,$E$31) -> 30 | D33: =INDEX(Bonds!F:F,$E$31) -> 21.75 | E33: =INDEX(Bonds!J:J,$E$31) -> 51.126 | F33: =INDEX(Bonds!N:N,$E$31) -> 3.0159 | G33: =F33/100 -> 0.030159 | H33: 0.2503324 | I33: =$H$31*H33 -> 24592.801 | J33: =I33/E33 -> 481.02338 | K33: =H33*D33 -> 5.4447298 | L33: =H33*C33 -> 7.5099721 | M33: =I33*(1+G33) -> 25334.495
B34: T-BOND 6% 15/02/26 | C34: =INDEX(Bonds!C:C,$E$31) -> -0.8 | D34: =INDEX(Bonds!G:G,$E$31) -> 7.922 | E34: =INDEX(Bonds!K:K,$E$31) -> 133.75 | F34: =INDEX(Bonds!O:O,$E$31) -> 2.2638 | G34: =F34/100 -> 0.022638 | H34: 0.16503266 | I34: =$H$31*H34 -> 16212.905 | J34: =I34/E34 -> 121.21798 | K34: =H34*D34 -> 1.3073888 | L34: =H34*C34 -> -0.13202613 | M34: =I34*(1+G34) -> 16579.933
B35: T-BOND 6 3/8% 15/08/27 | C35: =INDEX(Bonds!D:D,$E$31) -> 2.4 | D35: =INDEX(Bonds!H:H,$E$31) -> 8.7418 | E35: =INDEX(Bonds!L:L,$E$31) -> 140.8594 | F35: =INDEX(Bonds!P:P,$E$31) -> 2.3505 | G35: =F35/100 -> 0.023505 | H35: 0.4 | I35: =$H$31*H35 -> 39296.233 | J35: =I35/E35 -> 278.97487 | K35: =H35*D35 -> 3.49672 | L35: =H35*C35 -> 0.96 | M35: =I35*(1+G35) -> 40219.891
B36: T-BOND 5 1/4% 15/11/28 | C36: =INDEX(Bonds!E:E,$E$31) -> 6.7 | D36: =INDEX(Bonds!I:I,$E$31) -> 9.8736 | E36: =INDEX(Bonds!M:M,$E$31) -> 130.9688 | F36: =INDEX(Bonds!Q:Q,$E$31) -> 2.4391 | G36: =F36/100 -> 0.024391 | H36: 0.18463493 | I36: =$H$31*H36 -> 18138.643 | J36: =I36/E36 -> 138.49591 | K36: =H36*D36 -> 1.8230115 | L36: =H36*C36 -> 1.237054 | M36: =I36*(1+G36) -> 18581.063
B37: TOTAL | H37: =SUM(H33:H36) -> 1 | I37: =SUM(I33:I36) -> 98240.583 | K37: =SUM(K33:K36) -> 12.07185 | L37: =SUM(L33:L36) -> 9.575 | M37: =SUM(M33:M36) -> 100715.38
B39: CONSTRAINT CHECK
B40: Empirical average duration of the 4 bonds | E40: =AVERAGE(D33:D36) -> 12.07185
B41: Portfolio duration | E41: =K37 -> 12.07185
B42: Duration constraint (ptf <= average) | E42: =IF(K37<=AVERAGE(D33:D36)+0.0000001,"RESPECTED","VIOLATED") -> RESPECTED
B43: Empirical average spread of the 4 bonds | E43: =AVERAGE(C33:C36) -> 9.575
B44: Portfolio spread | E44: =L37 -> 9.575
B45: Spread constraint (ptf <= average) | E45: =IF(L37<=AVERAGE(C33:C36)+0.0000001,"RESPECTED","VIOLATED") -> RESPECTED
B46: Maximum weight on a single bond | E46: =MAX(H33:H36) -> 0.4
B47: 40% constraint per bond | E47: =IF(MAX(H33:H36)<=0.4000001,"RESPECTED","VIOLATED") -> RESPECTED
B48: Sum of weights | E48: =H37 -> 1
B50: RESULTS
...

Sheet 2_CVaR_t1
A2: POINT 2 - Mean-CVaR 3% frontier and investor's optimal portfolio - rebalancing 1 (15/05/2025)
G3: Valuation date | H3: 45792 | M3: MEAN-CVaR 3% EFFICIENT FRONTIER (no short selling)
G4: Sample rows in the Stocks Returns sheet | H4: 2 : 2498
A5: Date | B5: R risky ptf | C5: Loss L = -R | D5: X = final wealth | E5: u(X) | G5: Number of observations T | H5: =COUNT($B$6:$B$2502) -> 2497 | M5: Average return | N5: CVaR 3% | O5: w1 | P5: w2 | Q5: w3 | R5: w4 | S5: STARR
A6: ='Stocks Returns'!A2 -> 42298 | B6: =SUMPRODUCT('Stocks Returns'!B2:E2,$H$10:$K$10) -> -0.010418992 | C6: =-B6 -> 0.010418992 | D6: =1+$H$13+$H$19*(B6-$H$13) -> 0.99279778 | E6: =$H$22*D6-$H$23*D6^2-LN(1+$H$24*EXP(1-D6^3)) -> 1.5872294 | G6: Tail level alpha | H6: 0.03 | M6: 0.00064734709 | N6: 0.041445084 | O6: 0.080881658 | P6: 0.78778015 | Q6: 0 | R6: 0.13133819 | S6: =(M6-$H$13)/N6 -> 0.013367721
A7: ='Stocks Returns'!A3 -> 42299 | B7: =SUMPRODUCT('Stocks Returns'!B3:E3,$H$10:$K$10) -> 0.014112553 | C7: =-B7 -> -0.014112553 | D7: =1+$H$13+$H$19*(B7-$H$13) -> 1.0098227 | E7: =$H$22*D7-$H$23*D7^2-LN(1+$H$24*EXP(1-D7^3)) -> 1.6041633 | G7: k = ROUNDUP(T*alpha) - tail observations | H7: =ROUNDUP(H5*H6,0) -> 75 | M7: 0.00065045656 | N7: 0.041633287 | O7: 0.077588342 | P7: 0.79334893 | Q7: 0 | R7: 0.12906273 | S7: =(M7-$H$13)/N7 -> 0.013381979
A8: ='Stocks Returns'!A4 -> 42300 | B8: =SUMPRODUCT('Stocks Returns'!B4:E4,$H$10:$K$10) -> 0.0082931637 | C8: =-B8 -> -0.0082931637 | D8: =1+$H$13+$H$19*(B8-$H$13) -> 1.005784 | E8: =$H$22*D8-$H$23*D8^2-LN(1+$H$24*EXP(1-D8^3)) -> 1.6002517 | M8: 0.00065356602 | N8: 0.041457692 | O8: 0.074311457 | P8: 0.79895911 | Q8: 0 | R8: 0.12672944 | S8: =(M8-$H$13)/N8 -> 0.013513662
A9: ='Stocks Returns'!A5 -> 42303 | B9: =SUMPRODUCT('Stocks Returns'!B5:E5,$H$10:$K$10) -> 0.012767851 | C9: =-B9 -> -0.012767851 | D9: =1+$H$13+$H$19*(B9-$H$13) -> 1.0088894 | E9: =$H$22*D9-$H$23*D9^2-LN(1+$H$24*EXP(1-D9^3)) -> 1.6032654 | G9: Risky portfolio weights w* (Solver variable cells) | H9: WARNER BROS DISCOVERY | I9: VISA 'A' | J9: MICROCHIP TECH. | K9: CONOCOPHILLIPS | M9: 0.00065667548 | N9: 0.041650864 | O9: 0.069953459 | P9: 0.80184465 | Q9: 0 | R9: 0.12820189 | S9: =(M9-$H$13)/N9 -> 0.013525643
A10: ='Stocks Returns'!A6 -> 42304 | B10: =SUMPRODUCT('Stocks Returns'!B6:E6,$H$10:$K$10) -> -0.0086761187 | C10: =-B10 -> 0.0086761187 | D10: =1+$H$13+$H$19*(B10-$H$13) -> 0.99400733 | E10: =$H$22*D10-$H$23*D10^2-LN(1+$H$24*EXP(1-D10^3)) -> 1.5884707 | H10: 0 | I10: 0.93991483 | J10: 0.058150325 | K10: 0.0019348481 | M10: 0.00065978495 | N10: 0.041473334 | O10: 0.066254493 | P10: 0.8063911 | Q10: 0 | R10: 0.12735441 | S10: =(M10-$H$13)/N10 -> 0.013658516
A11: ='Stocks Returns'!A7 -> 42305 | B11: =SUMPRODUCT('Stocks Returns'!B7:E7,$H$10:$K$10) -> 0.017194586 | C11: =-B11 -> -0.017194586 | D11: =1+$H$13+$H$19*(B11-$H$13) -> 1.0119616 | E11: =$H$22*D11-$H$23*D11^2-LN(1+$H$24*EXP(1-D11^3)) -> 1.606208 | G11: Sum of weights (constraint = 1, no short selling) | H11: =SUM(H10:K10) -> 1 | M11: 0.00066289441 | N11: 0.041671054 | O11: 0.062555527 | P11: 0.81093754 | Q11: 0 | R11: 0.12650693 | S11: =(M11-$H$13)/N11 -> 0.013668328
A12: ='Stocks Returns'!A8 -> 42306 | B12: =SUMPRODUCT('Stocks Returns'!B8:E8,$H$10:$K$10) -> -0.0056811277 | C12: =-B12 -> 0.0056811277 | D12: =1+$H$13+$H$19*(B12-$H$13) -> 0.99608585 | E12: =$H$22*D12-$H$23*D12^2-LN(1+$H$24*EXP(1-D12^3)) -> 1.5905902 | G12: Annual IRR of the bond portfolio | H12: ='1_Bonds'!E27 -> 0.02379441 | M12: 0.00066600387 | N12: 0.041494336 | O12: 0.059456999 | P12: 0.81699722 | Q12: 0 | R12: 0.12354578 | S12: =(M12-$H$13)/N12 -> 0.013801477
A13: ='Stocks Returns'!A9 -> 42307 | B13: =SUMPRODUCT('Stocks Returns'!B9:E9,$H$10:$K$10) -> -0.010039268 | C13: =-B13 -> 0.010039268 | D13: =1+$H$13+$H$19*(B13-$H$13) -> 0.9930613 | E13: =$H$22*D13-$H$23*D13^2-LN(1+$H$24*EXP(1-D13^3)) -> 1.5875003 | G13: Daily risk-free rate rf | H13: =(1+H12)^(1/252)-1 -> 9.3320763e-05 | M13: 0.00066911334 | N13: 0.041692493 | O13: 0.056348755 | P13: 0.82303241 | Q13: 0 | R13: 0.12061883 | S13: =(M13-$H$13)/N13 -> 0.013810462
A14: ='Stocks Returns'!A10 -> 42310 | B14: =SUMPRODUCT('Stocks Returns'!B10:E10,$H$10:$K$10) -> -0.027812229 | C14: =-B14 -> 0.027812229 | D14: =1+$H$13+$H$19*(B14-$H$13) -> 0.98072687 | E14: =$H$22*D14-$H$23*D14^2-LN(1+$H$24*EXP(1-D14^3)) -> 1.5745283 | G14: Average daily return of the risky portfolio | H14: =AVERAGE($B$6:$B$2502) -> 0.00073752153 | M14: 0.0006722228 | N14: 0.041521844 | O14: 0.053394524 | P14: 0.82945575 | Q14: 0 | R14: 0.11714973 | S14: =(M14-$H$13)/N14 -> 0.013942108
A15: ='Stocks Returns'!A11 -> 42311 | B15: =SUMPRODUCT('Stocks Returns'!B11:E11,$H$10:$K$10) -> 0.033467839 | C15: =-B15 -> -0.033467839 | D15: =1+$H$13+$H$19*(B15-$H$13) -> 1.0232552 | E15: =$H$22*D15-$H$23*D15^2-LN(1+$H$24*EXP(1-D15^3)) -> 1.6166916 | G15: VaR 3% daily (loss, positive sign) | H15: =-SMALL($B$6:$B$2502,H7) -> 0.028802031 | M15: 0.00067533226 | N15: 0.04172372 | O15: 0.050417381 | P15: 0.83582134 | Q15: 0 | R15: 0.11376128 | S15: =(M15-$H$13)/N15 -> 0.013949176
A16: ='Stocks Returns'!A12 -> 42312 | B16: =SUMPRODUCT('Stocks Returns'!B12:E12,$H$10:$K$10) -> 0.0056187349 | C16: =-B16 -> -0.0056187349 | D16: =1+$H$13+$H$19*(B16-$H$13) -> 1.003928 | E16: =$H$22*D16-$H$23*D16^2-LN(1+$H$24*EXP(1-D16^3)) -> 1.5984319 | G16: CVaR 3% daily = average of the k worst returns (loss, positive sign) | H16: =-(SUMIF($B$6:$B$2502,"<"&-H15)+(-H15)*(H7-COUNTIF($B$6:$B$2502,"<"&-H15)))/H7 -> 0.042674545 | M16: 0.00067844173 | N16: 0.041742357 | O16: 0.047404175 | P16: 0.84209605 | Q16: 0 | R16: 0.11049977 | S16: =(M16-$H$13)/N16 -> 0.01401744
A17: ='Stocks Returns'!A13 -> 42313 | B17: =SUMPRODUCT('Stocks Returns'!B13:E13,$H$10:$K$10) -> 0.0096326851 | C17: =-B17 -> -0.0096326851 | D17: =1+$H$13+$H$19*(B17-$H$13) -> 1.0067136 | E17: =$H$22*D17-$H$23*D17^2-LN(1+$H$24*EXP(1-D17^3)) -> 1.601158 | G17: STARR = (mu - rf) / CVaR 3% | H17: =(H14-H13)/H16 -> 0.015095668 | M17: 0.00068155119 | N17: 0.041761225 | O17: 0.044390969 | P17: 0.84837076 | Q17: 0 | R17: 0.10723827 | S17: =(M17-$H$13)/N17 -> 0.014085565
A18: ='Stocks Returns'!A14 -> 42314 | B18: =SUMPRODUCT('Stocks Returns'!B14:E14,$H$10:$K$10) -> -0.0061382578 | C18: =-B18 -> 0.0061382578 | D18: =1+$H$13+$H$19*(B18-$H$13) -> 0.99576861 | E18: =$H$22*D18-$H$23*D18^2-LN(1+$H$24*EXP(1-D18^3)) -> 1.5902678 | M18: 0.00068466065 | N18: 0.041779985 | O18: 0.040892851 | P18: 0.85342338 | Q18: 0 | R18: 0.10568376 | S18: =(M18-$H$13)/N18 -> 0.014153664
A19: ='Stocks Returns'!A15 -> 42317 | B19: =SUMPRODUCT('Stocks Returns'!B15:E15,$H$10:$K$10) -> -0.0085558904 | C19: =-B19 -> 0.0085558904 | D19: =1+$H$13+$H$19*(B19-$H$13) -> 0.99409077 | E19: =$H$22*D19-$H$23*D19^2-LN(1+$H$24*EXP(1-D19^3)) -> 1.5885561 | G19: lambda = share invested in the risky portfolio | H19: 0.694 | M19: 0.00068777012 | N19: 0.041804898 | O19: 0.038017061 | P19: 0.86004441 | Q19: 0 | R19: 0.10193853 | S19: =(M19-$H$13)/N19 -> 0.01421961
A20: ='Stocks Returns'!A16 -> 42318 | B20: =SUMPRODUCT('Stocks Returns'!B16:E16,$H$10:$K$10) -> 0.016547154 | C20: =-B20 -> -0.016547154 | D20: =1+$H$13+$H$19*(B20-$H$13) -> 1.0115123 | E20: =$H$22*D20-$H$23*D20^2-LN(1+$H$24*EXP(1-D20^3)) -> 1.6057801 | G20: 1 - lambda = share in the risk-free asset | H20: =1-H19 -> 0.306 | M20: 0.00069087958 | N20: 0.041832838 | O20: 0.034362489 | P20: 0.86470274 | Q20: 0 | R20: 0.10093478 | S20: =(M20-$H$13)/N20 -> 0.014284443
A21: ='Stocks Returns'!A17 -> 42319 | B21: =SUMPRODUCT('Stocks Returns'!B17:E17,$H$10:$K$10) -> -0.0036645628 | C21: =-B21 -> 0.0036645628 | D21: =1+$H$13+$H$19*(B21-$H$13) -> 0.99748535 | E21: =$H$22*D21-$H$23*D21^2-LN(1+$H$24*EXP(1-D21^3)) -> 1.5920076 | M21: 0.00069398904 | N21: 0.041860779 | O21: 0.030707916 | P21: 0.86936106 | Q21: 0 | R21: 0.099931021 | S21: =(M21-$H$13)/N21 -> 0.01434919
A22: ='Stocks Returns'!A18 -> 42320 | B22: =SUMPRODUCT('Stocks Returns'!B18:E18,$H$10:$K$10) -> -0.011281921 | C22: =-B22 -> 0.011281921 | D22: =1+$H$13+$H$19*(B22-$H$13) -> 0.9921989 | E22: =$H$22*D22-$H$23*D22^2-LN(1+$H$24*EXP(1-D22^3)) -> 1.5866127 | G22: Parameter a (utility) | H22: 4 | M22: 0.0006970985 | N22: 0.041888719 | O22: 0.027053344 | P22: 0.87401939 | Q22: 0 | R22: 0.098927266 | S22: =(M22-$H$13)/N22 -> 0.014413851
A23: ='Stocks Returns'!A19 -> 42321 | B23: =SUMPRODUCT('Stocks Returns'!B19:E19,$H$10:$K$10) -> -0.0033211667 | C23: =-B23 -> 0.0033211667 | D23: =1+$H$13+$H$19*(B23-$H$13) -> 0.99772367 | E23: =$H$22*D23-$H$23*D23^2-LN(1+$H$24*EXP(1-D23^3)) -> 1.5922482 | G23: Parameter b (utility) | H23: 2 | M23: 0.00070020797 | N23: 0.041736515 | O23: 0.023156669 | P23: 0.87806757 | Q23: 0 | R23: 0.098775761 | S23: =(M23-$H$13)/N23 -> 0.014540917
A24: ='Stocks Returns'!A20 -> 42324 | B24: =SUMPRODUCT('Stocks Returns'!B20:E20,$H$10:$K$10) -> 0.0099960375 | C24: =-B24 -> -0.0099960375 | D24: =1+$H$13+$H$19*(B24-$H$13) -> 1.0069658 | E24: =$H$22*D24-$H$23*D24^2-LN(1+$H$24*EXP(1-D24^3)) -> 1.6014032 | G24: Parameter c (utility) | H24: 0.5 | M24: 0.00070331743 | N24: 0.041953002 | O24: 0.019225834 | P24: 0.88202966 | Q24: 0 | R24: 0.098744509 | S24: =(M24-$H$13)/N24 -> 0.014540001
A25: ='Stocks Returns'!A21 -> 42325 | B25: =SUMPRODUCT('Stocks Returns'!B21:E21,$H$10:$K$10) -> -0.00068610053 | C25: =-B25 -> 0.00068610053 | D25: =1+$H$13+$H$19*(B25-$H$13) -> 0.9995524 | E25: =$H$22*D25-$H$23*D25^2-LN(1+$H$24*EXP(1-D25^3)) -> 1.5940869 | G25: u(x) = a*x - b*x^2 - LN(1 + c*e^(1-x^3)) | M25: 0.00070642689 | N25: 0.041985683 | O25: 0.015294999 | P25: 0.88599174 | Q25: 0 | R25: 0.098713257 | S25: =(M25-$H$13)/N25 -> 0.014602743
A26: ='Stocks Returns'!A22 -> 42326 | B26: =SUMPRODUCT('Stocks Returns'!B22:E22,$H$10:$K$10) -> 0.02059157 | C26: =-B26 -> -0.02059157 | D26: =1+$H$13+$H$19*(B26-$H$13) -> 1.0143191 | E26: =$H$22*D26-$H$23*D26^2-LN(1+$H$24*EXP(1-D26^3)) -> 1.60844 | M26: 0.00070953636 | N26: 0.042018364 | O26: 0.011364165 | P26: 0.88995383 | Q26: 0 | R26: 0.098682005 | S26: =(M26-$H$13)/N26 -> 0.014665388
A27: ='Stocks Returns'!A23 -> 42327 | B27: =SUMPRODUCT('Stocks Returns'!B23:E23,$H$10:$K$10) -> -0.0034064673 | C27: =-B27 -> 0.0034064673 | D27: =1+$H$13+$H$19*(B27-$H$13) -> 0.99766447 | E27: =$H$22*D27-$H$23*D27^2-LN(1+$H$24*EXP(1-D27^3)) -> 1.5921885 | G27: E[u(X)] (Solver objective function on w* and lambda) | H27: =AVERAGE($E$6:$E$2502) -> 1.5948523 | M27: 0.00071264582 | N27: 0.042053616 | O27: 0.0082425113 | P27: 0.89595523 | Q27: 0 | R27: 0.09580226 | S27: =(M27-$H$13)/N27 -> 0.014727035
A28: ='Stocks Returns'!A24 -> 42328 | B28: =SUMPRODUCT('Stocks Returns'!B24:E24,$H$10:$K$10) -> 0.00069282336 | C28: =-B28 -> -0.00069282336 | D28: =1+$H$13+$H$19*(B28-$H$13) -> 1.0005094 | E28: =$H$22*D28-$H$23*D28^2-LN(1+$H$24*EXP(1-D28^3)) -> 1.5950437 | G28: E[X] | H28: =AVERAGE($D$6:$D$2502) -> 1.0005404 | M28: 0.00071575528 | N28: 0.042089182 | O28: 0.0051259082 | P28: 0.90196935 | Q28: 0 | R28: 0.092904739 | S28: =(M28-$H$13)/N28 -> 0.014788468
A29: ='Stocks Returns'!A25 -> 42331 | B29: =SUMPRODUCT('Stocks Returns'!B25:E25,$H$10:$K$10) -> -0.0018822016 | C29: =-B29 -> 0.0018822016 | D29: =1+$H$13+$H$19*(B29-$H$13) -> 0.99872231 | E29: =$H$22*D29-$H$23*D29^2-LN(1+$H$24*EXP(1-D29^3)) -> 1.5932539 | G29: Certainty equivalent CE (goal seek on H30 = 0) | H29: 1.0003176 | M29: 0.00071886475 | N29: 0.042126342 | O29: 0.00096558006 | P29: 0.90535307 | Q29: 0 | R29: 0.093681352 | S29: =(M29-$H$13)/N29 -> 0.014849236
A30: ='Stocks Returns'!A26 -> 42332 | B30: =SUMPRODUCT('Stocks Returns'!B26:E26,$H$10:$K$10) -> -0.0028942624 | C30: =-B30 -> 0.0028942624 | D30: =1+$H$13+$H$19*(B30-$H$13) -> 0.99801994 | E30: =$H$22*D30-$H$23*D30^2-LN(1+$H$24*EXP(1-D30^3)) -> 1.592547 | G30: Check: u(CE) - E[u(X)] (should be 0) | H30: =H22*H29-H23*H29^2-LN(1+H24*EXP(1-H29^3))-H27 -> 1.7297275e-13 | M30: 0.00072197421 | N30: 0.042181043 | O30: 0 | P30: 0.90906952 | Q30: 0.0097117959 | R30: 0.081218688 | S30: =(M30-$H$13)/N30 -> 0.014903696
A31: ='Stocks Returns'!A27 -> 42333 | B31: =SUMPRODUCT('Stocks Returns'!B27:E27,$H$10:$K$10) -> -0.0028407415 | C31: =-B31 -> 0.0028407415 | D31: =1+$H$13+$H$19*(B31-$H$13) -> 0.99805708 | E31: =$H$22*D31-$H$23*D31^2-LN(1+$H$24*EXP(1-D31^3)) -> 1.5925844 | G31: Daily risk premium = E[X] - CE | H31: =H28-H29 -> 0.00022282459 | M31: 0.00072508367 | N31: 0.042258493 | O31: 0 | P31: 0.9148837 | Q31: 0.01984602 | R31: 0.065270284 | S31: =(M31-$H$13)/N31 -> 0.014949963
A32: ='Stocks Returns'!A28 -> 42334 | B32: =SUMPRODUCT('Stocks Returns'!B28:E28,$H$10:$K$10) -> 0 | C32: =-B32 -> 0 | D32: =1+$H$13+$H$19*(B32-$H$13) -> 1.0000286 | E32: =$H$22*D32-$H$23*D32^2-LN(1+$H$24*EXP(1-D32^3)) -> 1.5945634 | G32: Annualized risk premium (x252) | H32: =H31*252 -> 0.056151796 | M32: 0.00072819314 | N32: 0.04235254 | O32: 0 | P32: 0.92014965 | Q32: 0.030670034 | R32: 0.04918032 | S32: =(M32-$H$13)/N32 -> 0.014990184
A33: ='Stocks Returns'!A29 -> 42335 | B33: =SUMPRODUCT('Stocks Returns'!B29:E29,$H$10:$K$10) -> 0.0039418578 | C33: =-B33 -> -0.0039418578 | D33: =1+$H$13+$H$19*(B33-$H$13) -> 1.0027642 | E33: =$H$22*D33-$H$23*D33^2-LN(1+$H$24*EXP(1-D33^3)) -> 1.5972838 | G33: Absolute risk aversion ARA(CE) = -u''/u' | H33: =-( (H22*(H29+0.00001)-H23*(H29+0.00001)^2-LN(1+H24*EXP(1-(H29+0.00001)^3))) -2*(H22*H29-H23*H29^2-LN(1+H24*EXP(1-H29^3))) +(H22*(H29-0.00001)-H23*(H29-0.00001)^2-LN(1+H24*EXP(1-(H29-0.00001)^3))) )/0.00001^2 / ( ((H22*(H29+0.00001)-H23*(H29+0.00001)^2-LN(1+H24*EXP(1-(H29+0.00001)^3))) -(H22*(H29-0.00001)-H23*(H29-0.00001)^2-LN(1+H24*EXP(1-(H29-0.00001)^3))))/(2*0.00001) ) -> 4.007633 | M33: 0.0007313026 | N33: 0.042446808 | O33: 0 | P33: 0.92568971 | Q33: 0.041149153 | R33: 0.033161136 | S33: =(M33-$H$13)/N33 -> 0.015030149
A34: ='Stocks Returns'!A30 -> 42338 | B34: =SUMPRODUCT('Stocks Returns'!B30:E30,$H$10:$K$10) -> -0.0090311261 | C34: =-B34 -> 0.0090311261 | D34: =1+$H$13+$H$19*(B34-$H$13) -> 0.99376095 | E34: =$H$22*D34-$H$23*D34^2-LN(1+$H$24*EXP(1-D34^3)) -> 1.5882183 | M34: 0.00073441206 | N34: 0.042544308 | O34: 0 | P34: 0.93244013 | Q34: 0.05010539 | R34: 0.017454482 | S34: =(M34-$H$13)/N34 -> 0.015068791
A35: ='Stocks Returns'!A31 -> 42339 | B35: =SUMPRODUCT('Stocks Returns'!B31:E31,$H$10:$K$10) -> 0.010979514 | C35: =-B35 -> -0.010979514 | D35: =1+$H$13+$H$19*(B35-$H$13) -> 1.0076483 | E35: =$H$22*D35-$H$23*D35^2-LN(1+$H$24*EXP(1-D35^3)) -> 1.6020656 | M35: 0.00073752153 | N35: 0.042674545 | O35: 0 | P35: 0.93991483 | Q35: 0.058150325 | R35: 0.0019348481 | S35: =(M35-$H$13)/N35 -> 0.015095668
A36: ='Stocks Returns'!A32 -> 42340 | B36: =SUMPRODUCT('Stocks Returns'!B32:E32,$H$10:$K$10) -> -0.012500651 | C36: =-B36 -> 0.012500651 | D36: =1+$H$13+$H$19*(B36-$H$13) -> 0.9913531 | E36: =$H$22*D36-$H$23*D36^2-LN(1+$H$24*EXP(1-D36^3)) -> 1.5857393 | M36: 0.00074063099 | N36: 0.042945575 | O36: 0 | P36: 1 | Q36: 0 | R36: 0 | S36: =(M36-$H$13)/N36 -> 0.015072804
A37: ='Stocks Returns'!A33 -> 42341 | B37: =SUMPRODUCT('Stocks Returns'!B33:E33,$H$10:$K$10) -> -0.0092399752 | C37: =-B37 -> 0.0092399752 | D37: =1+$H$13+$H$19*(B37-$H$13) -> 0.99361601 | E37: =$H$22*D37-$H$23*D37^2-LN(1+$H$24*EXP(1-D37^3)) -> 1.5880697
A38: ='Stocks Returns'!A34 -> 42342 | B38: =SUMPRODUCT('Stocks Returns'!B34:E34,$H$10:$K$10) -> 0.026493258 | C38: =-B38 -> -0.026493258 | D38: =1+$H$13+$H$19*(B38-$H$13) -> 1.0184149 | E38: =$H$22*D38-$H$23*D38^2-LN(1+$H$24*EXP(1-D38^3)) -> 1.6122632
A39: ='Stocks Returns'!A35 -> 42345 | B39: =SUMPRODUCT('Stocks Returns'!B35:E35,$H$10:$K$10) -> -0.010867093 | C39: =-B39 -> 0.010867093 | D39: =1+$H$13+$H$19*(B39-$H$13) -> 0.99248679 | E39: =$H$22*D39-$H$23*D39^2-LN(1+$H$24*EXP(1-D39^3)) -> 1.5869094
A40: ='Stocks Returns'!A36 -> 42346 | B40: =SUMPRODUCT('Stocks Returns'!B36:E36,$H$10:$K$10) -> -0.0062841315 | C40: =-B40 -> 0.0062841315 | D40: =1+$H$13+$H$19*(B40-$H$13) -> 0.99566737 | E40: =$H$22*D40-$H$23*D40^2-LN(1+$H$24*EXP(1-D40^3)) -> 1.5901648
A41: ='Stocks Returns'!A37 -> 42347 | B41: =SUMPRODUCT('Stocks Returns'!B37:E37,$H$10:$K$10) -> -0.015019741 | C41: =-B41 -> 0.015019741 | D41: =1+$H$13+$H$19*(B41-$H$13) -> 0.98960486 | E41: =$H$22*D41-$H$23*D41^2-LN(1+$H$24*EXP(1-D41^3)) -> 1.5839251
...

Sheet 2_CVaR_t2
A2: POINT 2 - Mean-CVaR 3% frontier and investor's optimal portfolio - rebalancing 2 (16/06/2025)
G3: Valuation date | H3: 45824 | M3: MEAN-CVaR 3% EFFICIENT FRONTIER (no short selling)
G4: Sample rows in the Stocks Returns sheet | H4: 2 : 2520
A5: Date | B5: R risky ptf | C5: Loss L = -R | D5: X = final wealth | E5: u(X) | G5: Number of observations T | H5: =COUNT($B$6:$B$2524) -> 2519 | M5: Average return | N5: CVaR 3% | O5: w1 | P5: w2 | Q5: w3 | R5: w4 | S5: STARR
A6: ='Stocks Returns'!A2 -> 42298 | B6: =SUMPRODUCT('Stocks Returns'!B2:E2,$H$10:$K$10) -> -0.010315385 | C6: =-B6 -> 0.010315385 | D6: =1+$H$13+$H$19*(B6-$H$13) -> 0.99301713 | E6: =$H$22*D6-$H$23*D6^2-LN(1+$H$24*EXP(1-D6^3)) -> 1.587455 | G6: Tail level alpha | H6: 0.03 | M6: 0.00064060391 | N6: 0.041388884 | O6: 0.082538734 | P6: 0.77877316 | Q6: 0 | R6: 0.13868811 | S6: =(M6-$H$13)/N6 -> 0.013092217
A7: ='Stocks Returns'!A3 -> 42299 | B7: =SUMPRODUCT('Stocks Returns'!B3:E3,$H$10:$K$10) -> 0.014562536 | C7: =-B7 -> -0.014562536 | D7: =1+$H$13+$H$19*(B7-$H$13) -> 1.0099341 | E7: =$H$22*D7-$H$23*D7^2-LN(1+$H$24*EXP(1-D7^3)) -> 1.6042703 | G7: k = ROUNDUP(T*alpha) - tail observations | H7: =ROUNDUP(H5*H6,0) -> 76 | M7: 0.00064382268 | N7: 0.041572984 | O7: 0.080236723 | P7: 0.78881477 | Q7: 0 | R7: 0.1309485 | S7: =(M7-$H$13)/N7 -> 0.013111665
A8: ='Stocks Returns'!A4 -> 42300 | B8: =SUMPRODUCT('Stocks Returns'!B4:E4,$H$10:$K$10) -> 0.0082199748 | C8: =-B8 -> -0.0082199748 | D8: =1+$H$13+$H$19*(B8-$H$13) -> 1.0056212 | E8: =$H$22*D8-$H$23*D8^2-LN(1+$H$24*EXP(1-D8^3)) -> 1.6000926 | M8: 0.00064704146 | N8: 0.041581075 | O8: 0.075255022 | P8: 0.79232559 | Q8: 0 | R8: 0.13241939 | S8: =(M8-$H$13)/N8 -> 0.013186523
A9: ='Stocks Returns'!A5 -> 42303 | B9: =SUMPRODUCT('Stocks Returns'!B5:E5,$H$10:$K$10) -> 0.012218608 | C9: =-B9 -> -0.012218608 | D9: =1+$H$13+$H$19*(B9-$H$13) -> 1.0083402 | E9: =$H$22*D9-$H$23*D9^2-LN(1+$H$24*EXP(1-D9^3)) -> 1.6027352 | G9: Risky portfolio weights w* (Solver variable cells) | H9: WARNER BROS DISCOVERY | I9: VISA 'A' | J9: MICROCHIP TECH. | K9: CONOCOPHILLIPS | M9: 0.00065026023 | N9: 0.041595028 | O9: 0.071586778 | P9: 0.79903749 | Q9: 0 | R9: 0.12937573 | S9: =(M9-$H$13)/N9 -> 0.013259483
A10: ='Stocks Returns'!A6 -> 42304 | B10: =SUMPRODUCT('Stocks Returns'!B6:E6,$H$10:$K$10) -> -0.0087623104 | C10: =-B10 -> 0.0087623104 | D10: =1+$H$13+$H$19*(B10-$H$13) -> 0.99407322 | E10: =$H$22*D10-$H$23*D10^2-LN(1+$H$24*EXP(1-D10^3)) -> 1.5885381 | H10: 0 | I10: 0.92027206 | J10: 0.076343536 | K10: 0.0033844055 | M10: 0.000653479 | N10: 0.041609352 | O10: 0.067535692 | P10: 0.80481636 | Q10: 0 | R10: 0.12764795 | S10: =(M10-$H$13)/N10 -> 0.013332276
A11: ='Stocks Returns'!A7 -> 42305 | B11: =SUMPRODUCT('Stocks Returns'!B7:E7,$H$10:$K$10) -> 0.017137916 | C11: =-B11 -> -0.017137916 | D11: =1+$H$13+$H$19*(B11-$H$13) -> 1.0116854 | E11: =$H$22*D11-$H$23*D11^2-LN(1+$H$24*EXP(1-D11^3)) -> 1.605945 | G11: Sum of weights (constraint = 1, no short selling) | H11: =SUM(H10:K10) -> 1 | M11: 0.00065669778 | N11: 0.041623888 | O11: 0.063266503 | P11: 0.81006367 | Q11: 0 | R11: 0.12666983 | S11: =(M11-$H$13)/N11 -> 0.01340495
A12: ='Stocks Returns'!A8 -> 42306 | B12: =SUMPRODUCT('Stocks Returns'!B8:E8,$H$10:$K$10) -> -0.0060222051 | C12: =-B12 -> 0.0060222051 | D12: =1+$H$13+$H$19*(B12-$H$13) -> 0.99593649 | E12: =$H$22*D12-$H$23*D12^2-LN(1+$H$24*EXP(1-D12^3)) -> 1.5904385 | G12: Annual IRR of the bond portfolio | H12: ='1_Bonds'!E52 -> 0.025191215 | M12: 0.00065991655 | N12: 0.041638937 | O12: 0.058469047 | P12: 0.81402352 | Q12: 0 | R12: 0.12750743 | S12: =(M12-$H$13)/N12 -> 0.013477407
A13: ='Stocks Returns'!A9 -> 42307 | B13: =SUMPRODUCT('Stocks Returns'!B9:E9,$H$10:$K$10) -> -0.0094683728 | C13: =-B13 -> 0.0094683728 | D13: =1+$H$13+$H$19*(B13-$H$13) -> 0.9935931 | E13: =$H$22*D13-$H$23*D13^2-LN(1+$H$24*EXP(1-D13^3)) -> 1.5880462 | G13: Daily risk-free rate rf | H13: =(1+H12)^(1/252)-1 -> 9.8731645e-05 | M13: 0.00066313533 | N13: 0.041471379 | O13: 0.054597319 | P13: 0.8202395 | Q13: 0 | R13: 0.12516318 | S13: =(M13-$H$13)/N13 -> 0.013609475
A14: ='Stocks Returns'!A10 -> 42310 | B14: =SUMPRODUCT('Stocks Returns'!B10:E10,$H$10:$K$10) -> -0.026945441 | C14: =-B14 -> 0.026945441 | D14: =1+$H$13+$H$19*(B14-$H$13) -> 0.98170869 | E14: =$H$22*D14-$H$23*D14^2-LN(1+$H$24*EXP(1-D14^3)) -> 1.5755826 | G14: Average daily return of the risky portfolio | H14: =AVERAGE($B$6:$B$2524) -> 0.0007275108 | M14: 0.0006663541 | N14: 0.041677955 | O14: 0.049733954 | P14: 0.82403872 | Q14: 0 | R14: 0.12622732 | S14: =(M14-$H$13)/N14 -> 0.013619249
A15: ='Stocks Returns'!A11 -> 42311 | B15: =SUMPRODUCT('Stocks Returns'!B11:E11,$H$10:$K$10) -> 0.032789169 | C15: =-B15 -> -0.032789169 | D15: =1+$H$13+$H$19*(B15-$H$13) -> 1.0223282 | E15: =$H$22*D15-$H$23*D15^2-LN(1+$H$24*EXP(1-D15^3)) -> 1.6158511 | G15: VaR 3% daily (loss, positive sign) | H15: =-SMALL($B$6:$B$2524,H7) -> 0.029215281 | M15: 0.00066957287 | N15: 0.041701263 | O15: 0.044419523 | P15: 0.82673862 | Q15: 0 | R15: 0.12884185 | S15: =(M15-$H$13)/N15 -> 0.013688823
A16: ='Stocks Returns'!A12 -> 42312 | B16: =SUMPRODUCT('Stocks Returns'!B12:E12,$H$10:$K$10) -> 0.0055586526 | C16: =-B16 -> -0.0055586526 | D16: =1+$H$13+$H$19*(B16-$H$13) -> 1.0038115 | E16: =$H$22*D16-$H$23*D16^2-LN(1+$H$24*EXP(1-D16^3)) -> 1.5983172 | G16: CVaR 3% daily = average of the k worst returns (loss, positive sign) | H16: =-(SUMIF($B$6:$B$2524,"<"&-H15)+(-H15)*(H7-COUNTIF($B$6:$B$2524,"<"&-H15)))/H7 -> 0.042734434 | M16: 0.00067279165 | N16: 0.041725983 | O16: 0.040723972 | P16: 0.83338398 | Q16: 0 | R16: 0.12589205 | S16: =(M16-$H$13)/N16 -> 0.013757854
A17: ='Stocks Returns'!A13 -> 42313 | B17: =SUMPRODUCT('Stocks Returns'!B13:E13,$H$10:$K$10) -> 0.0090019243 | C17: =-B17 -> -0.0090019243 | D17: =1+$H$13+$H$19*(B17-$H$13) -> 1.0061529 | E17: =$H$22*D17-$H$23*D17^2-LN(1+$H$24*EXP(1-D17^3)) -> 1.6006118 | G17: STARR = (mu - rf) / CVaR 3% | H17: =(H14-H13)/H16 -> 0.014713642 | M17: 0.00067601042 | N17: 0.041755465 | O17: 0.040784231 | P17: 0.8491828 | Q17: 0 | R17: 0.11003297 | S17: =(M17-$H$13)/N17 -> 0.013825227
A18: ='Stocks Returns'!A14 -> 42314 | B18: =SUMPRODUCT('Stocks Returns'!B14:E14,$H$10:$K$10) -> -0.0060477859 | C18: =-B18 -> 0.0060477859 | D18: =1+$H$13+$H$19*(B18-$H$13) -> 0.9959191 | E18: =$H$22*D18-$H$23*D18^2-LN(1+$H$24*EXP(1-D18^3)) -> 1.5904208 | M18: 0.00067922919 | N18: 0.041784747 | O18: 0.034240761 | P18: 0.84888735 | Q18: 0 | R18: 0.11687189 | S18: =(M18-$H$13)/N18 -> 0.013892571
A19: ='Stocks Returns'!A15 -> 42317 | B19: =SUMPRODUCT('Stocks Returns'!B15:E15,$H$10:$K$10) -> -0.0084214718 | C19: =-B19 -> 0.0084214718 | D19: =1+$H$13+$H$19*(B19-$H$13) -> 0.99430499 | E19: =$H$22*D19-$H$23*D19^2-LN(1+$H$24*EXP(1-D19^3)) -> 1.5887753 | G19: lambda = share invested in the risky portfolio | H19: 0.68 | M19: 0.00068244797 | N19: 0.041818631 | O19: 0.029092405 | P19: 0.85199201 | Q19: 0 | R19: 0.11891559 | S19: =(M19-$H$13)/N19 -> 0.013958284
A20: ='Stocks Returns'!A16 -> 42318 | B20: =SUMPRODUCT('Stocks Returns'!B16:E16,$H$10:$K$10) -> 0.015935747 | C20: =-B20 -> -0.015935747 | D20: =1+$H$13+$H$19*(B20-$H$13) -> 1.0108679 | E20: =$H$22*D20-$H$23*D20^2-LN(1+$H$24*EXP(1-D20^3)) -> 1.6051649 | G20: 1 - lambda = share in the risk-free asset | H20: =1-H19 -> 0.32 | M20: 0.00068566674 | N20: 0.041854938 | O20: 0.025962047 | P20: 0.86001482 | Q20: 0 | R20: 0.11402314 | S20: =(M20-$H$13)/N20 -> 0.014023079
A21: ='Stocks Returns'!A17 -> 42319 | B21: =SUMPRODUCT('Stocks Returns'!B17:E17,$H$10:$K$10) -> -0.0036456616 | C21: =-B21 -> 0.0036456616 | D21: =1+$H$13+$H$19*(B21-$H$13) -> 0.99755254 | E21: =$H$22*D21-$H$23*D21^2-LN(1+$H$24*EXP(1-D21^3)) -> 1.5920755 | M21: 0.00068888552 | N21: 0.041890855 | O21: 0.022507049 | P21: 0.86724644 | Q21: 0 | R21: 0.11024652 | S21: =(M21-$H$13)/N21 -> 0.014087893
A22: ='Stocks Returns'!A18 -> 42320 | B22: =SUMPRODUCT('Stocks Returns'!B18:E18,$H$10:$K$10) -> -0.011387943 | C22: =-B22 -> 0.011387943 | D22: =1+$H$13+$H$19*(B22-$H$13) -> 0.99228779 | E22: =$H$22*D22-$H$23*D22^2-LN(1+$H$24*EXP(1-D22^3)) -> 1.5867043 | G22: Parameter a (utility) | H22: 4 | M22: 0.00069210429 | N22: 0.041928486 | O22: 0.018488291 | P22: 0.87310409 | Q22: 0 | R22: 0.10840762 | S22: =(M22-$H$13)/N22 -> 0.014152017
A23: ='Stocks Returns'!A19 -> 42321 | B23: =SUMPRODUCT('Stocks Returns'!B19:E19,$H$10:$K$10) -> -0.0035613195 | C23: =-B23 -> 0.0035613195 | D23: =1+$H$13+$H$19*(B23-$H$13) -> 0.9976099 | E23: =$H$22*D23-$H$23*D23^2-LN(1+$H$24*EXP(1-D23^3)) -> 1.5921334 | G23: Parameter b (utility) | H23: 2 | M23: 0.00069532306 | N23: 0.041969147 | O23: 0.014453213 | P23: 0.87892196 | Q23: 0 | R23: 0.10662482 | S23: =(M23-$H$13)/N23 -> 0.014215
A24: ='Stocks Returns'!A20 -> 42324 | B24: =SUMPRODUCT('Stocks Returns'!B20:E20,$H$10:$K$10) -> 0.0099919828 | C24: =-B24 -> -0.0099919828 | D24: =1+$H$13+$H$19*(B24-$H$13) -> 1.0068261 | E24: =$H$22*D24-$H$23*D24^2-LN(1+$H$24*EXP(1-D24^3)) -> 1.6012674 | G24: Parameter c (utility) | H24: 0.5 | M24: 0.00069854184 | N24: 0.041822444 | O24: 0.010418136 | P24: 0.88473984 | Q24: 0 | R24: 0.10484202 | S24: =(M24-$H$13)/N24 -> 0.014341826
A25: ='Stocks Returns'!A21 -> 42325 | B25: =SUMPRODUCT('Stocks Returns'!B21:E21,$H$10:$K$10) -> -0.0006297326 | C25: =-B25 -> 0.0006297326 | D25: =1+$H$13+$H$19*(B25-$H$13) -> 0.99960338 | E25: =$H$22*D25-$H$23*D25^2-LN(1+$H$24*EXP(1-D25^3)) -> 1.594138 | G25: u(x) = a*x - b*x^2 - LN(1 + c*e^(1-x^3)) | M25: 0.00070176061 | N25: 0.041864759 | O25: 0.0067115404 | P25: 0.89135828 | Q25: 0 | R25: 0.10193018 | S25: =(M25-$H$13)/N25 -> 0.014404214
A26: ='Stocks Returns'!A22 -> 42326 | B26: =SUMPRODUCT('Stocks Returns'!B22:E22,$H$10:$K$10) -> 0.020556343 | C26: =-B26 -> -0.020556343 | D26: =1+$H$13+$H$19*(B26-$H$13) -> 1.0140099 | E26: =$H$22*D26-$H$23*D26^2-LN(1+$H$24*EXP(1-D26^3)) -> 1.6081486 | M26: 0.00070497939 | N26: 0.041910385 | O26: 0.0032560712 | P26: 0.89858875 | Q26: 0 | R26: 0.098155181 | S26: =(M26-$H$13)/N26 -> 0.014465335
A27: ='Stocks Returns'!A23 -> 42327 | B27: =SUMPRODUCT('Stocks Returns'!B23:E23,$H$10:$K$10) -> -0.0032778145 | C27: =-B27 -> 0.0032778145 | D27: =1+$H$13+$H$19*(B27-$H$13) -> 0.99780268 | E27: =$H$22*D27-$H$23*D27^2-LN(1+$H$24*EXP(1-D27^3)) -> 1.5923279 | G27: E[u(X)] (Solver objective function on w* and lambda) | H27: =AVERAGE($E$6:$E$2524) -> 1.5948477 | M27: 0.00070819816 | N27: 0.04196213 | O27: 0.00034988102 | P27: 0.90585841 | Q27: 0.0012409428 | R27: 0.092550767 | S27: =(M27-$H$13)/N27 -> 0.014524203
A28: ='Stocks Returns'!A24 -> 42328 | B28: =SUMPRODUCT('Stocks Returns'!B24:E24,$H$10:$K$10) -> 0.00074309248 | C28: =-B28 -> -0.00074309248 | D28: =1+$H$13+$H$19*(B28-$H$13) -> 1.0005369 | E28: =$H$22*D28-$H$23*D28^2-LN(1+$H$24*EXP(1-D28^3)) -> 1.5950712 | G28: E[X] | H28: =AVERAGE($D$6:$D$2524) -> 1.0005263 | M28: 0.00071141693 | N28: 0.042209894 | O28: 0 | P28: 0.89523436 | Q28: 0.025518972 | R28: 0.079246664 | S28: =(M28-$H$13)/N28 -> 0.014515205
A29: ='Stocks Returns'!A25 -> 42331 | B29: =SUMPRODUCT('Stocks Returns'!B25:E25,$H$10:$K$10) -> -0.0021525285 | C29: =-B29 -> 0.0021525285 | D29: =1+$H$13+$H$19*(B29-$H$13) -> 0.99856787 | E29: =$H$22*D29-$H$23*D29^2-LN(1+$H$24*EXP(1-D29^3)) -> 1.5930987 | G29: Certainty equivalent CE (goal seek on H30 = 0) | H29: 1.0003131 | M29: 0.00071463571 | N29: 0.042114833 | O29: 0 | P29: 0.8842453 | Q29: 0.050959877 | R29: 0.064794823 | S29: =(M29-$H$13)/N29 -> 0.014624398
A30: ='Stocks Returns'!A26 -> 42332 | B30: =SUMPRODUCT('Stocks Returns'!B26:E26,$H$10:$K$10) -> -0.0025143384 | C30: =-B30 -> 0.0025143384 | D30: =1+$H$13+$H$19*(B30-$H$13) -> 0.99832184 | E30: =$H$22*D30-$H$23*D30^2-LN(1+$H$24*EXP(1-D30^3)) -> 1.5928511 | G30: Check: u(CE) - E[u(X)] (should be 0) | H30: =H22*H29-H23*H29^2-LN(1+H24*EXP(1-H29^3))-H27 -> 1.7164048e-13 | M30: 0.00071785448 | N30: 0.042213683 | O30: 0 | P30: 0.89666066 | Q30: 0.054050673 | R30: 0.049288666 | S30: =(M30-$H$13)/N30 -> 0.014666402
A31: ='Stocks Returns'!A27 -> 42333 | B31: =SUMPRODUCT('Stocks Returns'!B27:E27,$H$10:$K$10) -> -0.0028395672 | C31: =-B31 -> 0.0028395672 | D31: =1+$H$13+$H$19*(B31-$H$13) -> 0.99810069 | E31: =$H$22*D31-$H$23*D31^2-LN(1+$H$24*EXP(1-D31^3)) -> 1.5926284 | G31: Daily risk premium = E[X] - CE | H31: =H28-H29 -> 0.00021324739 | M31: 0.00072107326 | N31: 0.042317428 | O31: 0 | P31: 0.90185762 | Q31: 0.064034701 | R31: 0.034107681 | S31: =(M31-$H$13)/N31 -> 0.014706509
A32: ='Stocks Returns'!A28 -> 42334 | B32: =SUMPRODUCT('Stocks Returns'!B28:E28,$H$10:$K$10) -> 0 | C32: =-B32 -> 0 | D32: =1+$H$13+$H$19*(B32-$H$13) -> 1.0000316 | E32: =$H$22*D32-$H$23*D32^2-LN(1+$H$24*EXP(1-D32^3)) -> 1.5945665 | G32: Annualized risk premium (x252) | H32: =H31*252 -> 0.053738342 | M32: 0.00072429203 | N32: 0.042606235 | O32: 0 | P32: 0.9121881 | Q32: 0.069116461 | R32: 0.018695443 | S32: =(M32-$H$13)/N32 -> 0.014682367
A33: ='Stocks Returns'!A29 -> 42335 | B33: =SUMPRODUCT('Stocks Returns'!B29:E29,$H$10:$K$10) -> 0.0040571008 | C33: =-B33 -> -0.0040571008 | D33: =1+$H$13+$H$19*(B33-$H$13) -> 1.0027904 | E33: =$H$22*D33-$H$23*D33^2-LN(1+$H$24*EXP(1-D33^3)) -> 1.5973097 | G33: Absolute risk aversion ARA(CE) = -u''/u' | H33: =-( (H22*(H29+0.00001)-H23*(H29+0.00001)^2-LN(1+H24*EXP(1-(H29+0.00001)^3))) -2*(H22*H29-H23*H29^2-LN(1+H24*EXP(1-H29^3))) +(H22*(H29-0.00001)-H23*(H29-0.00001)^2-LN(1+H24*EXP(1-(H29-0.00001)^3))) )/0.00001^2 / ( ((H22*(H29+0.00001)-H23*(H29+0.00001)^2-LN(1+H24*EXP(1-(H29+0.00001)^3))) -(H22*(H29-0.00001)-H23*(H29-0.00001)^2-LN(1+H24*EXP(1-(H29-0.00001)^3))))/(2*0.00001) ) -> 4.0075271 | M33: 0.0007275108 | N33: 0.042558861 | O33: 0 | P33: 0.92027206 | Q33: 0.076343536 | R33: 0.0033844055 | S33: =(M33-$H$13)/N33 -> 0.014774342
A34: ='Stocks Returns'!A30 -> 42338 | B34: =SUMPRODUCT('Stocks Returns'!B30:E30,$H$10:$K$10) -> -0.0085863958 | C34: =-B34 -> 0.0085863958 | D34: =1+$H$13+$H$19*(B34-$H$13) -> 0.99419285 | E34: =$H$22*D34-$H$23*D34^2-LN(1+$H$24*EXP(1-D34^3)) -> 1.5886606 | M34: 0.00073072958 | N34: 0.044761694 | O34: 0 | P34: 0.66360087 | Q34: 0.33639913 | R34: 0 | S34: =(M34-$H$13)/N34 -> 0.014119169
A35: ='Stocks Returns'!A31 -> 42339 | B35: =SUMPRODUCT('Stocks Returns'!B31:E31,$H$10:$K$10) -> 0.010849916 | C35: =-B35 -> -0.010849916 | D35: =1+$H$13+$H$19*(B35-$H$13) -> 1.0074095 | E35: =$H$22*D35-$H$23*D35^2-LN(1+$H$24*EXP(1-D35^3)) -> 1.6018341 | M35: 0.00073394835 | N35: 0.053876991 | O35: 0 | P35: 0.33180043 | Q35: 0.66819957 | R35: 0 | S35: =(M35-$H$13)/N35 -> 0.01179013
A36: ='Stocks Returns'!A32 -> 42340 | B36: =SUMPRODUCT('Stocks Returns'!B32:E32,$H$10:$K$10) -> -0.013028082 | C36: =-B36 -> 0.013028082 | D36: =1+$H$13+$H$19*(B36-$H$13) -> 0.9911725 | E36: =$H$22*D36-$H$23*D36^2-LN(1+$H$24*EXP(1-D36^3)) -> 1.5855525 | M36: 0.00073716713 | N36: 0.06747821 | O36: 0 | P36: 0 | Q36: 1 | R36: 0 | S36: =(M36-$H$13)/N36 -> 0.0094613577
A37: ='Stocks Returns'!A33 -> 42341 | B37: =SUMPRODUCT('Stocks Returns'!B33:E33,$H$10:$K$10) -> -0.0091691963 | C37: =-B37 -> 0.0091691963 | D37: =1+$H$13+$H$19*(B37-$H$13) -> 0.99379654 | E37: =$H$22*D37-$H$23*D37^2-LN(1+$H$24*EXP(1-D37^3)) -> 1.5882548
A38: ='Stocks Returns'!A34 -> 42342 | B38: =SUMPRODUCT('Stocks Returns'!B34:E34,$H$10:$K$10) -> 0.026320399 | C38: =-B38 -> -0.026320399 | D38: =1+$H$13+$H$19*(B38-$H$13) -> 1.0179295 | E38: =$H$22*D38-$H$23*D38^2-LN(1+$H$24*EXP(1-D38^3)) -> 1.6118137
A39: ='Stocks Returns'!A35 -> 42345 | B39: =SUMPRODUCT('Stocks Returns'!B35:E35,$H$10:$K$10) -> -0.01098673 | C39: =-B39 -> 0.01098673 | D39: =1+$H$13+$H$19*(B39-$H$13) -> 0.99256062 | E39: =$H$22*D39-$H$23*D39^2-LN(1+$H$24*EXP(1-D39^3)) -> 1.5869854
A40: ='Stocks Returns'!A36 -> 42346 | B40: =SUMPRODUCT('Stocks Returns'!B36:E36,$H$10:$K$10) -> -0.0063692038 | C40: =-B40 -> 0.0063692038 | D40: =1+$H$13+$H$19*(B40-$H$13) -> 0.99570054 | E40: =$H$22*D40-$H$23*D40^2-LN(1+$H$24*EXP(1-D40^3)) -> 1.5901986
A41: ='Stocks Returns'!A37 -> 42347 | B41: =SUMPRODUCT('Stocks Returns'!B37:E37,$H$10:$K$10) -> -0.014994612 | C41: =-B41 -> 0.014994612 | D41: =1+$H$13+$H$19*(B41-$H$13) -> 0.98983526 | E41: =$H$22*D41-$H$23*D41^2-LN(1+$H$24*EXP(1-D41^3)) -> 1.5841649
...

Sheet 2_CVaR_t3
A2: POINT 2 - Mean-CVaR 3% frontier and investor's optimal portfolio - rebalancing 3 (15/07/2025)
G3: Valuation date | H3: 45853 | M3: MEAN-CVaR 3% EFFICIENT FRONTIER (no short selling)
G4: Sample rows in the Stocks Returns sheet | H4: 2 : 2541
A5: Date | B5: R risky ptf | C5: Loss L = -R | D5: X = final wealth | E5: u(X) | G5: Number of observations T | H5: =COUNT($B$6:$B$2545) -> 2540 | M5: Average return | N5: CVaR 3% | O5: w1 | P5: w2 | Q5: w3 | R5: w4 | S5: STARR
A6: ='Stocks Returns'!A2 -> 42298 | B6: =SUMPRODUCT('Stocks Returns'!B2:E2,$H$10:$K$10) -> -0.010013056 | C6: =-B6 -> 0.010013056 | D6: =1+$H$13+$H$19*(B6-$H$13) -> 0.99336492 | E6: =$H$22*D6-$H$23*D6^2-LN(1+$H$24*EXP(1-D6^3)) -> 1.5878122 | G6: Tail level alpha | H6: 0.03 | M6: 0.00062458208 | N6: 0.041555754 | O6: 0.089992058 | P6: 0.76267839 | Q6: 0 | R6: 0.14732955 | S6: =(M6-$H$13)/N6 -> 0.012607762
A7: ='Stocks Returns'!A3 -> 42299 | B7: =SUMPRODUCT('Stocks Returns'!B3:E3,$H$10:$K$10) -> 0.015744271 | C7: =-B7 -> -0.015744271 | D7: =1+$H$13+$H$19*(B7-$H$13) -> 1.0105193 | E7: =$H$22*D7-$H$23*D7^2-LN(1+$H$24*EXP(1-D7^3)) -> 1.6048313 | G7: k = ROUNDUP(T*alpha) - tail observations | H7: =ROUNDUP(H5*H6,0) -> 77 | M7: 0.00062907736 | N7: 0.041557403 | O7: 0.084908967 | P7: 0.77365486 | Q7: 0 | R7: 0.14143617 | S7: =(M7-$H$13)/N7 -> 0.012715432
A8: ='Stocks Returns'!A4 -> 42300 | B8: =SUMPRODUCT('Stocks Returns'!B4:E4,$H$10:$K$10) -> 0.0080665168 | C8: =-B8 -> -0.0080665168 | D8: =1+$H$13+$H$19*(B8-$H$13) -> 1.0054059 | E8: =$H$22*D8-$H$23*D8^2-LN(1+$H$24*EXP(1-D8^3)) -> 1.5998822 | M8: 0.00063357265 | N8: 0.041562506 | O8: 0.080995291 | P8: 0.7871625 | Q8: 0 | R8: 0.13184221 | S8: =(M8-$H$13)/N8 -> 0.012822028
A9: ='Stocks Returns'!A5 -> 42303 | B9: =SUMPRODUCT('Stocks Returns'!B5:E5,$H$10:$K$10) -> 0.01095333 | C9: =-B9 -> -0.01095333 | D9: =1+$H$13+$H$19*(B9-$H$13) -> 1.0073285 | E9: =$H$22*D9-$H$23*D9^2-LN(1+$H$24*EXP(1-D9^3)) -> 1.6017555 | G9: Risky portfolio weights w* (Solver variable cells) | H9: WARNER BROS DISCOVERY | I9: VISA 'A' | J9: MICROCHIP TECH. | K9: CONOCOPHILLIPS | M9: 0.00063806793 | N9: 0.041580129 | O9: 0.073590648 | P9: 0.793114 | Q9: 0 | R9: 0.13329535 | S9: =(M9-$H$13)/N9 -> 0.012924705
A10: ='Stocks Returns'!A6 -> 42304 | B10: =SUMPRODUCT('Stocks Returns'!B6:E6,$H$10:$K$10) -> -0.0088973986 | C10: =-B10 -> 0.0088973986 | D10: =1+$H$13+$H$19*(B10-$H$13) -> 0.99410795 | E10: =$H$22*D10-$H$23*D10^2-LN(1+$H$24*EXP(1-D10^3)) -> 1.5885737 | H10: 0 | I10: 0.87042953 | J10: 0.12957047 | K10: 0 | M10: 0.00064256322 | N10: 0.041607268 | O10: 0.065559968 | P10: 0.79771045 | Q10: 0 | R10: 0.13672958 | S10: =(M10-$H$13)/N10 -> 0.013024315
A11: ='Stocks Returns'!A7 -> 42305 | B11: =SUMPRODUCT('Stocks Returns'!B7:E7,$H$10:$K$10) -> 0.016861505 | C11: =-B11 -> -0.016861505 | D11: =1+$H$13+$H$19*(B11-$H$13) -> 1.0112634 | E11: =$H$22*D11-$H$23*D11^2-LN(1+$H$24*EXP(1-D11^3)) -> 1.6055426 | G11: Sum of weights (constraint = 1, no short selling) | H11: =SUM(H10:K10) -> 1 | M11: 0.0006470585 | N11: 0.041633612 | O11: 0.059171861 | P11: 0.80586223 | Q11: 0 | R11: 0.13496591 | S11: =(M11-$H$13)/N11 -> 0.013124046
A12: ='Stocks Returns'!A8 -> 42306 | B12: =SUMPRODUCT('Stocks Returns'!B8:E8,$H$10:$K$10) -> -0.0070949108 | C12: =-B12 -> 0.0070949108 | D12: =1+$H$13+$H$19*(B12-$H$13) -> 0.99530841 | E12: =$H$22*D12-$H$23*D12^2-LN(1+$H$24*EXP(1-D12^3)) -> 1.5897994 | G12: Annual IRR of the bond portfolio | H12: ='1_Bonds'!E77 -> 0.025688709 | M12: 0.00065155379 | N12: 0.041660856 | O12: 0.053278121 | P12: 0.81508405 | Q12: 0 | R12: 0.13163783 | S12: =(M12-$H$13)/N12 -> 0.013223366
A13: ='Stocks Returns'!A9 -> 42307 | B13: =SUMPRODUCT('Stocks Returns'!B9:E9,$H$10:$K$10) -> -0.0078500636 | C13: =-B13 -> 0.0078500636 | D13: =1+$H$13+$H$19*(B13-$H$13) -> 0.99480548 | E13: =$H$22*D13-$H$23*D13^2-LN(1+$H$24*EXP(1-D13^3)) -> 1.5892866 | G13: Daily risk-free rate rf | H13: =(1+H12)^(1/252)-1 -> 0.00010065704 | M13: 0.00065604907 | N13: 0.041697972 | O13: 0.047253415 | P13: 0.82402241 | Q13: 0 | R13: 0.12872418 | S13: =(M13-$H$13)/N13 -> 0.013319401
A14: ='Stocks Returns'!A10 -> 42310 | B14: =SUMPRODUCT('Stocks Returns'!B10:E10,$H$10:$K$10) -> -0.024868746 | C14: =-B14 -> 0.024868746 | D14: =1+$H$13+$H$19*(B14-$H$13) -> 0.98347103 | E14: =$H$22*D14-$H$23*D14^2-LN(1+$H$24*EXP(1-D14^3)) -> 1.5774655 | G14: Average daily return of the risky portfolio | H14: =AVERAGE($B$6:$B$2545) -> 0.00071898306 | M14: 0.00066054436 | N14: 0.041553377 | O14: 0.039714343 | P14: 0.82968293 | Q14: 0 | R14: 0.13060272 | S14: =(M14-$H$13)/N14 -> 0.01347393
A15: ='Stocks Returns'!A11 -> 42311 | B15: =SUMPRODUCT('Stocks Returns'!B11:E11,$H$10:$K$10) -> 0.030826862 | C15: =-B15 -> -0.030826862 | D15: =1+$H$13+$H$19*(B15-$H$13) -> 1.0205643 | E15: =$H$22*D15-$H$23*D15^2-LN(1+$H$24*EXP(1-D15^3)) -> 1.6142418 | G15: VaR 3% daily (loss, positive sign) | H15: =-SMALL($B$6:$B$2545,H7) -> 0.029377076 | M15: 0.00066503964 | N15: 0.041787444 | O15: 0.037170538 | P15: 0.84615564 | Q15: 0 | R15: 0.11667382 | S15: =(M15-$H$13)/N15 -> 0.013506033
A16: ='Stocks Returns'!A12 -> 42312 | B16: =SUMPRODUCT('Stocks Returns'!B12:E12,$H$10:$K$10) -> 0.0054793428 | C16: =-B16 -> -0.0054793428 | D16: =1+$H$13+$H$19*(B16-$H$13) -> 1.0036829 | E16: =$H$22*D16-$H$23*D16^2-LN(1+$H$24*EXP(1-D16^3)) -> 1.5981906 | G16: CVaR 3% daily = average of the k worst returns (loss, positive sign) | H16: =-(SUMIF($B$6:$B$2545,"<"&-H15)+(-H15)*(H7-COUNTIF($B$6:$B$2545,"<"&-H15)))/H7 -> 0.042857275 | M16: 0.00066953493 | N16: 0.041657209 | O16: 0.034100412 | P16: 0.85076351 | Q16: 0.008739537 | R16: 0.10639654 | S16: =(M16-$H$13)/N16 -> 0.013656169
A17: ='Stocks Returns'!A13 -> 42313 | B17: =SUMPRODUCT('Stocks Returns'!B13:E13,$H$10:$K$10) -> 0.0072532254 | C17: =-B17 -> -0.0072532254 | D17: =1+$H$13+$H$19*(B17-$H$13) -> 1.0048643 | E17: =$H$22*D17-$H$23*D17^2-LN(1+$H$24*EXP(1-D17^3)) -> 1.5993517 | G17: STARR = (mu - rf) / CVaR 3% | H17: =(H14-H13)/H16 -> 0.014427562 | M17: 0.00067403021 | N17: 0.041703807 | O17: 0.028718659 | P17: 0.84915931 | Q17: 0.018463855 | R17: 0.10365817 | S17: =(M17-$H$13)/N17 -> 0.013748701
A18: ='Stocks Returns'!A14 -> 42314 | B18: =SUMPRODUCT('Stocks Returns'!B14:E14,$H$10:$K$10) -> -0.0057630629 | C18: =-B18 -> 0.0057630629 | D18: =1+$H$13+$H$19*(B18-$H$13) -> 0.99619542 | E18: =$H$22*D18-$H$23*D18^2-LN(1+$H$24*EXP(1-D18^3)) -> 1.5907014 | M18: 0.0006785255 | N18: 0.041933111 | O18: 0.023336906 | P18: 0.84755512 | Q18: 0.028188174 | R18: 0.1009198 | S18: =(M18-$H$13)/N18 -> 0.01378072
A19: ='Stocks Returns'!A15 -> 42317 | B19: =SUMPRODUCT('Stocks Returns'!B15:E15,$H$10:$K$10) -> -0.0079424567 | C19: =-B19 -> 0.0079424567 | D19: =1+$H$13+$H$19*(B19-$H$13) -> 0.99474394 | E19: =$H$22*D19-$H$23*D19^2-LN(1+$H$24*EXP(1-D19^3)) -> 1.5892238 | G19: lambda = share invested in the risky portfolio | H19: 0.666 | M19: 0.00068302078 | N19: 0.041988567 | O19: 0.016941673 | P19: 0.84670102 | Q19: 0.035513837 | R19: 0.10084347 | S19: =(M19-$H$13)/N19 -> 0.013869579
A20: ='Stocks Returns'!A16 -> 42318 | B20: =SUMPRODUCT('Stocks Returns'!B16:E16,$H$10:$K$10) -> 0.014286294 | C20: =-B20 -> -0.014286294 | D20: =1+$H$13+$H$19*(B20-$H$13) -> 1.0095483 | E20: =$H$22*D20-$H$23*D20^2-LN(1+$H$24*EXP(1-D20^3)) -> 1.6038997 | G20: 1 - lambda = share in the risk-free asset | H20: =1-H19 -> 0.334 | M20: 0.00068751607 | N20: 0.042048114 | O20: 0.012491496 | P20: 0.84727784 | Q20: 0.045104001 | R20: 0.095126659 | S20: =(M20-$H$13)/N20 -> 0.013956845
A21: ='Stocks Returns'!A17 -> 42319 | B21: =SUMPRODUCT('Stocks Returns'!B17:E17,$H$10:$K$10) -> -0.0034503142 | C21: =-B21 -> 0.0034503142 | D21: =1+$H$13+$H$19*(B21-$H$13) -> 0.99773571 | E21: =$H$22*D21-$H$23*D21^2-LN(1+$H$24*EXP(1-D21^3)) -> 1.5922604 | M21: 0.00069201135 | N21: 0.041937539 | O21: 0.0087465524 | P21: 0.85237424 | Q21: 0.05225531 | R21: 0.086623903 | S21: =(M21-$H$13)/N21 -> 0.014100835
A22: ='Stocks Returns'!A18 -> 42320 | B22: =SUMPRODUCT('Stocks Returns'!B18:E18,$H$10:$K$10) -> -0.011572156 | C22: =-B22 -> 0.011572156 | D22: =1+$H$13+$H$19*(B22-$H$13) -> 0.99232656 | E22: =$H$22*D22-$H$23*D22^2-LN(1+$H$24*EXP(1-D22^3)) -> 1.5867443 | G22: Parameter a (utility) | H22: 4 | M22: 0.00069650664 | N22: 0.042014017 | O22: 0.0049950754 | P22: 0.85749655 | Q22: 0.059373969 | R22: 0.078134402 | S22: =(M22-$H$13)/N22 -> 0.014182162
A23: ='Stocks Returns'!A19 -> 42321 | B23: =SUMPRODUCT('Stocks Returns'!B19:E19,$H$10:$K$10) -> -0.0042628553 | C23: =-B23 -> 0.0042628553 | D23: =1+$H$13+$H$19*(B23-$H$13) -> 0.99719456 | E23: =$H$22*D23-$H$23*D23^2-LN(1+$H$24*EXP(1-D23^3)) -> 1.5917137 | G23: Parameter b (utility) | H23: 2 | M23: 0.00070100192 | N23: 0.04227453 | O23: 0 | P23: 0.86215696 | Q23: 0.064675692 | R23: 0.073167344 | S23: =(M23-$H$13)/N23 -> 0.014201101
A24: ='Stocks Returns'!A20 -> 42324 | B24: =SUMPRODUCT('Stocks Returns'!B20:E20,$H$10:$K$10) -> 0.0096835535 | C24: =-B24 -> -0.0096835535 | D24: =1+$H$13+$H$19*(B24-$H$13) -> 1.0064829 | E24: =$H$22*D24-$H$23*D24^2-LN(1+$H$24*EXP(1-D24^3)) -> 1.6009333 | G24: Parameter c (utility) | H24: 0.5 | M24: 0.00070549721 | N24: 0.042391643 | O24: 0 | P24: 0.86867269 | Q24: 0.077275377 | R24: 0.054051937 | S24: =(M24-$H$13)/N24 -> 0.01426791
A25: ='Stocks Returns'!A21 -> 42325 | B25: =SUMPRODUCT('Stocks Returns'!B21:E21,$H$10:$K$10) -> -0.00040566832 | C25: =-B25 -> 0.00040566832 | D25: =1+$H$13+$H$19*(B25-$H$13) -> 0.99976344 | E25: =$H$22*D25-$H$23*D25^2-LN(1+$H$24*EXP(1-D25^3)) -> 1.5942982 | G25: u(x) = a*x - b*x^2 - LN(1 + c*e^(1-x^3)) | M25: 0.00070999249 | N25: 0.042522672 | O25: 0 | P25: 0.86997974 | Q25: 0.094119222 | R25: 0.035901033 | S25: =(M25-$H$13)/N25 -> 0.01432966
A26: ='Stocks Returns'!A22 -> 42326 | B26: =SUMPRODUCT('Stocks Returns'!B22:E22,$H$10:$K$10) -> 0.020528899 | C26: =-B26 -> -0.020528899 | D26: =1+$H$13+$H$19*(B26-$H$13) -> 1.0137059 | E26: =$H$22*D26-$H$23*D26^2-LN(1+$H$24*EXP(1-D26^3)) -> 1.6078616 | M26: 0.00071448778 | N26: 0.042675363 | O26: 0 | P26: 0.88247925 | Q26: 0.10184315 | R26: 0.015677591 | S26: =(M26-$H$13)/N26 -> 0.014383726
A27: ='Stocks Returns'!A23 -> 42327 | B27: =SUMPRODUCT('Stocks Returns'!B23:E23,$H$10:$K$10) -> -0.0028020326 | C27: =-B27 -> 0.0028020326 | D27: =1+$H$13+$H$19*(B27-$H$13) -> 0.99816747 | E27: =$H$22*D27-$H$23*D27^2-LN(1+$H$24*EXP(1-D27^3)) -> 1.5926956 | G27: E[u(X)] (Solver objective function on w* and lambda) | H27: =AVERAGE($E$6:$E$2545) -> 1.5948414 | M27: 0.00071898306 | N27: 0.042857275 | O27: 0 | P27: 0.87042953 | Q27: 0.12957047 | R27: 0 | S27: =(M27-$H$13)/N27 -> 0.014427562
A28: ='Stocks Returns'!A24 -> 42328 | B28: =SUMPRODUCT('Stocks Returns'!B24:E24,$H$10:$K$10) -> 0.00098366042 | C28: =-B28 -> -0.00098366042 | D28: =1+$H$13+$H$19*(B28-$H$13) -> 1.0006887 | E28: =$H$22*D28-$H$23*D28^2-LN(1+$H$24*EXP(1-D28^3)) -> 1.5952227 | G28: E[X] | H28: =AVERAGE($D$6:$D$2545) -> 1.0005125 | M28: 0.00072347835 | N28: 0.043229024 | O28: 0 | P28: 0.77371514 | Q28: 0.22628486 | R28: 0 | S28: =(M28-$H$13)/N28 -> 0.01440748
A29: ='Stocks Returns'!A25 -> 42331 | B29: =SUMPRODUCT('Stocks Returns'!B25:E25,$H$10:$K$10) -> -0.0030014395 | C29: =-B29 -> 0.0030014395 | D29: =1+$H$13+$H$19*(B29-$H$13) -> 0.99803466 | E29: =$H$22*D29-$H$23*D29^2-LN(1+$H$24*EXP(1-D29^3)) -> 1.5925618 | G29: Certainty equivalent CE (goal seek on H30 = 0) | H29: 1.0003067 | M29: 0.00072797363 | N29: 0.04434194 | O29: 0 | P29: 0.67700074 | Q29: 0.32299926 | R29: 0 | S29: =(M29-$H$13)/N29 -> 0.014147252
A30: ='Stocks Returns'!A26 -> 42332 | B30: =SUMPRODUCT('Stocks Returns'!B26:E26,$H$10:$K$10) -> -0.0017252335 | C30: =-B30 -> 0.0017252335 | D30: =1+$H$13+$H$19*(B30-$H$13) -> 0.99888461 | E30: =$H$22*D30-$H$23*D30^2-LN(1+$H$24*EXP(1-D30^3)) -> 1.593417 | G30: Check: u(CE) - E[u(X)] (should be 0) | H30: =H22*H29-H23*H29^2-LN(1+H24*EXP(1-H29^3))-H27 -> 1.6942003e-13 | M30: 0.00073246891 | N30: 0.046360125 | O30: 0 | P30: 0.58028635 | Q30: 0.41971365 | R30: 0 | S30: =(M30-$H$13)/N30 -> 0.013628347
A31: ='Stocks Returns'!A27 -> 42333 | B31: =SUMPRODUCT('Stocks Returns'!B27:E27,$H$10:$K$10) -> -0.0027285427 | C31: =-B31 -> 0.0027285427 | D31: =1+$H$13+$H$19*(B31-$H$13) -> 0.99821641 | E31: =$H$22*D31-$H$23*D31^2-LN(1+$H$24*EXP(1-D31^3)) -> 1.5927449 | G31: Daily risk premium = E[X] - CE | H31: =H28-H29 -> 0.00020579541 | M31: 0.0007369642 | N31: 0.048826518 | O31: 0 | P31: 0.48357196 | Q31: 0.51642804 | R31: 0 | S31: =(M31-$H$13)/N31 -> 0.013031999
A32: ='Stocks Returns'!A28 -> 42334 | B32: =SUMPRODUCT('Stocks Returns'!B28:E28,$H$10:$K$10) -> 0 | C32: =-B32 -> 0 | D32: =1+$H$13+$H$19*(B32-$H$13) -> 1.0000336 | E32: =$H$22*D32-$H$23*D32^2-LN(1+$H$24*EXP(1-D32^3)) -> 1.5945685 | G32: Annualized risk premium (x252) | H32: =H31*252 -> 0.051860443 | M32: 0.00074145948 | N32: 0.051807602 | O32: 0 | P32: 0.38685757 | Q32: 0.61314243 | R32: 0 | S32: =(M32-$H$13)/N32 -> 0.012368888
A33: ='Stocks Returns'!A29 -> 42335 | B33: =SUMPRODUCT('Stocks Returns'!B29:E29,$H$10:$K$10) -> 0.0045472978 | C33: =-B33 -> -0.0045472978 | D33: =1+$H$13+$H$19*(B33-$H$13) -> 1.0030621 | E33: =$H$22*D33-$H$23*D33^2-LN(1+$H$24*EXP(1-D33^3)) -> 1.5975782 | G33: Absolute risk aversion ARA(CE) = -u''/u' | H33: =-( (H22*(H29+0.00001)-H23*(H29+0.00001)^2-LN(1+H24*EXP(1-(H29+0.00001)^3))) -2*(H22*H29-H23*H29^2-LN(1+H24*EXP(1-H29^3))) +(H22*(H29-0.00001)-H23*(H29-0.00001)^2-LN(1+H24*EXP(1-(H29-0.00001)^3))) )/0.00001^2 / ( ((H22*(H29+0.00001)-H23*(H29+0.00001)^2-LN(1+H24*EXP(1-(H29+0.00001)^3))) -(H22*(H29-0.00001)-H23*(H29-0.00001)^2-LN(1+H24*EXP(1-(H29-0.00001)^3))))/(2*0.00001) ) -> 4.0073734 | M33: 0.00074595477 | N33: 0.055148203 | O33: 0 | P33: 0.29014318 | Q33: 0.70985682 | R33: 0 | S33: =(M33-$H$13)/N33 -> 0.011701156
A34: ='Stocks Returns'!A30 -> 42338 | B34: =SUMPRODUCT('Stocks Returns'!B30:E30,$H$10:$K$10) -> -0.0074458143 | C34: =-B34 -> 0.0074458143 | D34: =1+$H$13+$H$19*(B34-$H$13) -> 0.99507471 | E34: =$H$22*D34-$H$23*D34^2-LN(1+$H$24*EXP(1-D34^3)) -> 1.5895612 | M34: 0.00075045005 | N34: 0.058879633 | O34: 0 | P34: 0.19342878 | Q34: 0.80657122 | R34: 0 | S34: =(M34-$H$13)/N34 -> 0.011035956
